{"uuid": "7e4b1c97-dcac-49ad-9424-f0e163146b53", "children": ["6b6b2ab8-a393-44c3-a345-1f5ddf689d69", "3d1ad70f-8eb4-420f-8193-d302604019fd", "246c54da-dbe9-4f03-8fbe-818755e1dfe5", "1df70578-baf2-4cf0-b854-d4444f2ca327", "faa84880-608f-4141-92cc-135c9e2c9072", "7e20194d-b915-4f83-9e55-9709c2bdd51b", "4a6ee7f5-b9d7-46f7-8d6f-844554d32155", "f92019b5-0a79-4e8c-b525-b998cdb83106", "33bf06c5-81dd-4b45-8fd3-ab5fec20970e", "e6829572-71a5-4f1c-afa4-91dd3a13f103", "52e82f32-f06c-44dc-be1a-99a2112a12b3", "db8aa1a4-4d6c-49a1-88f3-c848f47adce1"], "befores": [{"name": "init_driver", "status": "broken", "statusDetails": {"message": "selenium.common.exceptions.WebDriverException: Message: 'chromedriver.exe' executable needs to be in PATH. Please see https://chromedriver.chromium.org/home\n\n", "trace": "  File \"/Users/shaikmohamedimran/IdeaProjects/Farmstack 2.0/venv/lib/python3.10/site-packages/pluggy/_callers.py\", line 39, in _multicall\n    res = hook_impl.function(*args)\n  File \"/Users/shaikmohamedimran/IdeaProjects/Farmstack 2.0/venv/lib/python3.10/site-packages/_pytest/fixtures.py\", line 1129, in pytest_fixture_setup\n    result = call_fixture_func(fixturefunc, request, kwargs)\n  File \"/Users/shaikmohamedimran/IdeaProjects/Farmstack 2.0/venv/lib/python3.10/site-packages/_pytest/fixtures.py\", line 901, in call_fixture_func\n    fixture_result = next(generator)\n  File \"/Users/shaikmohamedimran/IdeaProjects/Farmstack 2.0/Testcases/confitest.py\", line 18, in init_driver\n    driver = webdriver.Chrome(service=chrome_service)\n  File \"/Users/shaikmohamedimran/IdeaProjects/Farmstack 2.0/venv/lib/python3.10/site-packages/selenium/webdriver/chrome/webdriver.py\", line 80, in __init__\n    super().__init__(\n  File \"/Users/shaikmohamedimran/IdeaProjects/Farmstack 2.0/venv/lib/python3.10/site-packages/selenium/webdriver/chromium/webdriver.py\", line 101, in __init__\n    self.service.start()\n  File \"/Users/shaikmohamedimran/IdeaProjects/Farmstack 2.0/venv/lib/python3.10/site-packages/selenium/webdriver/common/service.py\", line 98, in start\n    raise err\n  File \"/Users/shaikmohamedimran/IdeaProjects/Farmstack 2.0/venv/lib/python3.10/site-packages/selenium/webdriver/common/service.py\", line 88, in start\n    self._start_process(self.path)\n  File \"/Users/shaikmohamedimran/IdeaProjects/Farmstack 2.0/venv/lib/python3.10/site-packages/selenium/webdriver/common/service.py\", line 209, in _start_process\n    raise WebDriverException(\n"}, "start": 1690363111571, "stop": 1690363143634}, {"name": "init_driver", "status": "broken", "statusDetails": {"message": "selenium.common.exceptions.WebDriverException: Message: 'chromedriver.exe' executable needs to be in PATH. Please see https://chromedriver.chromium.org/home\n\n", "trace": "  File \"/Users/shaikmohamedimran/IdeaProjects/Farmstack 2.0/venv/lib/python3.10/site-packages/pluggy/_callers.py\", line 39, in _multicall\n    res = hook_impl.function(*args)\n  File \"/Users/shaikmohamedimran/IdeaProjects/Farmstack 2.0/venv/lib/python3.10/site-packages/_pytest/fixtures.py\", line 1129, in pytest_fixture_setup\n    result = call_fixture_func(fixturefunc, request, kwargs)\n  File \"/Users/shaikmohamedimran/IdeaProjects/Farmstack 2.0/venv/lib/python3.10/site-packages/_pytest/fixtures.py\", line 901, in call_fixture_func\n    fixture_result = next(generator)\n  File \"/Users/shaikmohamedimran/IdeaProjects/Farmstack 2.0/Testcases/confitest.py\", line 18, in init_driver\n    driver = webdriver.Chrome(service=chrome_service)\n  File \"/Users/shaikmohamedimran/IdeaProjects/Farmstack 2.0/venv/lib/python3.10/site-packages/selenium/webdriver/chrome/webdriver.py\", line 80, in __init__\n    super().__init__(\n  File \"/Users/shaikmohamedimran/IdeaProjects/Farmstack 2.0/venv/lib/python3.10/site-packages/selenium/webdriver/chromium/webdriver.py\", line 101, in __init__\n    self.service.start()\n  File \"/Users/shaikmohamedimran/IdeaProjects/Farmstack 2.0/venv/lib/python3.10/site-packages/selenium/webdriver/common/service.py\", line 98, in start\n    raise err\n  File \"/Users/shaikmohamedimran/IdeaProjects/Farmstack 2.0/venv/lib/python3.10/site-packages/selenium/webdriver/common/service.py\", line 88, in start\n    self._start_process(self.path)\n  File \"/Users/shaikmohamedimran/IdeaProjects/Farmstack 2.0/venv/lib/python3.10/site-packages/selenium/webdriver/common/service.py\", line 209, in _start_process\n    raise WebDriverException(\n"}, "start": 1690363143705, "stop": 1690363144141}, {"name": "init_driver", "status": "broken", "statusDetails": {"message": "selenium.common.exceptions.WebDriverException: Message: 'chromedriver.exe' executable needs to be in PATH. Please see https://chromedriver.chromium.org/home\n\n", "trace": "  File \"/Users/shaikmohamedimran/IdeaProjects/Farmstack 2.0/venv/lib/python3.10/site-packages/pluggy/_callers.py\", line 39, in _multicall\n    res = hook_impl.function(*args)\n  File \"/Users/shaikmohamedimran/IdeaProjects/Farmstack 2.0/venv/lib/python3.10/site-packages/_pytest/fixtures.py\", line 1129, in pytest_fixture_setup\n    result = call_fixture_func(fixturefunc, request, kwargs)\n  File \"/Users/shaikmohamedimran/IdeaProjects/Farmstack 2.0/venv/lib/python3.10/site-packages/_pytest/fixtures.py\", line 901, in call_fixture_func\n    fixture_result = next(generator)\n  File \"/Users/shaikmohamedimran/IdeaProjects/Farmstack 2.0/Testcases/confitest.py\", line 18, in init_driver\n    driver = webdriver.Chrome(service=chrome_service)\n  File \"/Users/shaikmohamedimran/IdeaProjects/Farmstack 2.0/venv/lib/python3.10/site-packages/selenium/webdriver/chrome/webdriver.py\", line 80, in __init__\n    super().__init__(\n  File \"/Users/shaikmohamedimran/IdeaProjects/Farmstack 2.0/venv/lib/python3.10/site-packages/selenium/webdriver/chromium/webdriver.py\", line 101, in __init__\n    self.service.start()\n  File \"/Users/shaikmohamedimran/IdeaProjects/Farmstack 2.0/venv/lib/python3.10/site-packages/selenium/webdriver/common/service.py\", line 98, in start\n    raise err\n  File \"/Users/shaikmohamedimran/IdeaProjects/Farmstack 2.0/venv/lib/python3.10/site-packages/selenium/webdriver/common/service.py\", line 88, in start\n    self._start_process(self.path)\n  File \"/Users/shaikmohamedimran/IdeaProjects/Farmstack 2.0/venv/lib/python3.10/site-packages/selenium/webdriver/common/service.py\", line 209, in _start_process\n    raise WebDriverException(\n"}, "start": 1690363144168, "stop": 1690363144578}, {"name": "init_driver", "status": "broken", "statusDetails": {"message": "selenium.common.exceptions.WebDriverException: Message: 'chromedriver.exe' executable needs to be in PATH. Please see https://chromedriver.chromium.org/home\n\n", "trace": "  File \"/Users/shaikmohamedimran/IdeaProjects/Farmstack 2.0/venv/lib/python3.10/site-packages/pluggy/_callers.py\", line 39, in _multicall\n    res = hook_impl.function(*args)\n  File \"/Users/shaikmohamedimran/IdeaProjects/Farmstack 2.0/venv/lib/python3.10/site-packages/_pytest/fixtures.py\", line 1129, in pytest_fixture_setup\n    result = call_fixture_func(fixturefunc, request, kwargs)\n  File \"/Users/shaikmohamedimran/IdeaProjects/Farmstack 2.0/venv/lib/python3.10/site-packages/_pytest/fixtures.py\", line 901, in call_fixture_func\n    fixture_result = next(generator)\n  File \"/Users/shaikmohamedimran/IdeaProjects/Farmstack 2.0/Testcases/confitest.py\", line 18, in init_driver\n    driver = webdriver.Chrome(service=chrome_service)\n  File \"/Users/shaikmohamedimran/IdeaProjects/Farmstack 2.0/venv/lib/python3.10/site-packages/selenium/webdriver/chrome/webdriver.py\", line 80, in __init__\n    super().__init__(\n  File \"/Users/shaikmohamedimran/IdeaProjects/Farmstack 2.0/venv/lib/python3.10/site-packages/selenium/webdriver/chromium/webdriver.py\", line 101, in __init__\n    self.service.start()\n  File \"/Users/shaikmohamedimran/IdeaProjects/Farmstack 2.0/venv/lib/python3.10/site-packages/selenium/webdriver/common/service.py\", line 98, in start\n    raise err\n  File \"/Users/shaikmohamedimran/IdeaProjects/Farmstack 2.0/venv/lib/python3.10/site-packages/selenium/webdriver/common/service.py\", line 88, in start\n    self._start_process(self.path)\n  File \"/Users/shaikmohamedimran/IdeaProjects/Farmstack 2.0/venv/lib/python3.10/site-packages/selenium/webdriver/common/service.py\", line 209, in _start_process\n    raise WebDriverException(\n"}, "start": 1690363144605, "stop": 1690363145003}, {"name": "init_driver", "status": "broken", "statusDetails": {"message": "selenium.common.exceptions.WebDriverException: Message: 'chromedriver.exe' executable needs to be in PATH. Please see https://chromedriver.chromium.org/home\n\n", "trace": "  File \"/Users/shaikmohamedimran/IdeaProjects/Farmstack 2.0/venv/lib/python3.10/site-packages/pluggy/_callers.py\", line 39, in _multicall\n    res = hook_impl.function(*args)\n  File \"/Users/shaikmohamedimran/IdeaProjects/Farmstack 2.0/venv/lib/python3.10/site-packages/_pytest/fixtures.py\", line 1129, in pytest_fixture_setup\n    result = call_fixture_func(fixturefunc, request, kwargs)\n  File \"/Users/shaikmohamedimran/IdeaProjects/Farmstack 2.0/venv/lib/python3.10/site-packages/_pytest/fixtures.py\", line 901, in call_fixture_func\n    fixture_result = next(generator)\n  File \"/Users/shaikmohamedimran/IdeaProjects/Farmstack 2.0/Testcases/confitest.py\", line 18, in init_driver\n    driver = webdriver.Chrome(service=chrome_service)\n  File \"/Users/shaikmohamedimran/IdeaProjects/Farmstack 2.0/venv/lib/python3.10/site-packages/selenium/webdriver/chrome/webdriver.py\", line 80, in __init__\n    super().__init__(\n  File \"/Users/shaikmohamedimran/IdeaProjects/Farmstack 2.0/venv/lib/python3.10/site-packages/selenium/webdriver/chromium/webdriver.py\", line 101, in __init__\n    self.service.start()\n  File \"/Users/shaikmohamedimran/IdeaProjects/Farmstack 2.0/venv/lib/python3.10/site-packages/selenium/webdriver/common/service.py\", line 98, in start\n    raise err\n  File \"/Users/shaikmohamedimran/IdeaProjects/Farmstack 2.0/venv/lib/python3.10/site-packages/selenium/webdriver/common/service.py\", line 88, in start\n    self._start_process(self.path)\n  File \"/Users/shaikmohamedimran/IdeaProjects/Farmstack 2.0/venv/lib/python3.10/site-packages/selenium/webdriver/common/service.py\", line 209, in _start_process\n    raise WebDriverException(\n"}, "start": 1690363145045, "stop": 1690363145409}, {"name": "init_driver", "status": "broken", "statusDetails": {"message": "selenium.common.exceptions.WebDriverException: Message: 'chromedriver.exe' executable needs to be in PATH. Please see https://chromedriver.chromium.org/home\n\n", "trace": "  File \"/Users/shaikmohamedimran/IdeaProjects/Farmstack 2.0/venv/lib/python3.10/site-packages/pluggy/_callers.py\", line 39, in _multicall\n    res = hook_impl.function(*args)\n  File \"/Users/shaikmohamedimran/IdeaProjects/Farmstack 2.0/venv/lib/python3.10/site-packages/_pytest/fixtures.py\", line 1129, in pytest_fixture_setup\n    result = call_fixture_func(fixturefunc, request, kwargs)\n  File \"/Users/shaikmohamedimran/IdeaProjects/Farmstack 2.0/venv/lib/python3.10/site-packages/_pytest/fixtures.py\", line 901, in call_fixture_func\n    fixture_result = next(generator)\n  File \"/Users/shaikmohamedimran/IdeaProjects/Farmstack 2.0/Testcases/confitest.py\", line 18, in init_driver\n    driver = webdriver.Chrome(service=chrome_service)\n  File \"/Users/shaikmohamedimran/IdeaProjects/Farmstack 2.0/venv/lib/python3.10/site-packages/selenium/webdriver/chrome/webdriver.py\", line 80, in __init__\n    super().__init__(\n  File \"/Users/shaikmohamedimran/IdeaProjects/Farmstack 2.0/venv/lib/python3.10/site-packages/selenium/webdriver/chromium/webdriver.py\", line 101, in __init__\n    self.service.start()\n  File \"/Users/shaikmohamedimran/IdeaProjects/Farmstack 2.0/venv/lib/python3.10/site-packages/selenium/webdriver/common/service.py\", line 98, in start\n    raise err\n  File \"/Users/shaikmohamedimran/IdeaProjects/Farmstack 2.0/venv/lib/python3.10/site-packages/selenium/webdriver/common/service.py\", line 88, in start\n    self._start_process(self.path)\n  File \"/Users/shaikmohamedimran/IdeaProjects/Farmstack 2.0/venv/lib/python3.10/site-packages/selenium/webdriver/common/service.py\", line 209, in _start_process\n    raise WebDriverException(\n"}, "start": 1690363145437, "stop": 1690363145799}, {"name": "init_driver", "status": "broken", "statusDetails": {"message": "selenium.common.exceptions.WebDriverException: Message: 'chromedriver.exe' executable needs to be in PATH. Please see https://chromedriver.chromium.org/home\n\n", "trace": "  File \"/Users/shaikmohamedimran/IdeaProjects/Farmstack 2.0/venv/lib/python3.10/site-packages/pluggy/_callers.py\", line 39, in _multicall\n    res = hook_impl.function(*args)\n  File \"/Users/shaikmohamedimran/IdeaProjects/Farmstack 2.0/venv/lib/python3.10/site-packages/_pytest/fixtures.py\", line 1129, in pytest_fixture_setup\n    result = call_fixture_func(fixturefunc, request, kwargs)\n  File \"/Users/shaikmohamedimran/IdeaProjects/Farmstack 2.0/venv/lib/python3.10/site-packages/_pytest/fixtures.py\", line 901, in call_fixture_func\n    fixture_result = next(generator)\n  File \"/Users/shaikmohamedimran/IdeaProjects/Farmstack 2.0/Testcases/confitest.py\", line 18, in init_driver\n    driver = webdriver.Chrome(service=chrome_service)\n  File \"/Users/shaikmohamedimran/IdeaProjects/Farmstack 2.0/venv/lib/python3.10/site-packages/selenium/webdriver/chrome/webdriver.py\", line 80, in __init__\n    super().__init__(\n  File \"/Users/shaikmohamedimran/IdeaProjects/Farmstack 2.0/venv/lib/python3.10/site-packages/selenium/webdriver/chromium/webdriver.py\", line 101, in __init__\n    self.service.start()\n  File \"/Users/shaikmohamedimran/IdeaProjects/Farmstack 2.0/venv/lib/python3.10/site-packages/selenium/webdriver/common/service.py\", line 98, in start\n    raise err\n  File \"/Users/shaikmohamedimran/IdeaProjects/Farmstack 2.0/venv/lib/python3.10/site-packages/selenium/webdriver/common/service.py\", line 88, in start\n    self._start_process(self.path)\n  File \"/Users/shaikmohamedimran/IdeaProjects/Farmstack 2.0/venv/lib/python3.10/site-packages/selenium/webdriver/common/service.py\", line 209, in _start_process\n    raise WebDriverException(\n"}, "start": 1690363145840, "stop": 1690363146281}, {"name": "init_driver", "status": "broken", "statusDetails": {"message": "selenium.common.exceptions.WebDriverException: Message: 'chromedriver.exe' executable needs to be in PATH. Please see https://chromedriver.chromium.org/home\n\n", "trace": "  File \"/Users/shaikmohamedimran/IdeaProjects/Farmstack 2.0/venv/lib/python3.10/site-packages/pluggy/_callers.py\", line 39, in _multicall\n    res = hook_impl.function(*args)\n  File \"/Users/shaikmohamedimran/IdeaProjects/Farmstack 2.0/venv/lib/python3.10/site-packages/_pytest/fixtures.py\", line 1129, in pytest_fixture_setup\n    result = call_fixture_func(fixturefunc, request, kwargs)\n  File \"/Users/shaikmohamedimran/IdeaProjects/Farmstack 2.0/venv/lib/python3.10/site-packages/_pytest/fixtures.py\", line 901, in call_fixture_func\n    fixture_result = next(generator)\n  File \"/Users/shaikmohamedimran/IdeaProjects/Farmstack 2.0/Testcases/confitest.py\", line 18, in init_driver\n    driver = webdriver.Chrome(service=chrome_service)\n  File \"/Users/shaikmohamedimran/IdeaProjects/Farmstack 2.0/venv/lib/python3.10/site-packages/selenium/webdriver/chrome/webdriver.py\", line 80, in __init__\n    super().__init__(\n  File \"/Users/shaikmohamedimran/IdeaProjects/Farmstack 2.0/venv/lib/python3.10/site-packages/selenium/webdriver/chromium/webdriver.py\", line 101, in __init__\n    self.service.start()\n  File \"/Users/shaikmohamedimran/IdeaProjects/Farmstack 2.0/venv/lib/python3.10/site-packages/selenium/webdriver/common/service.py\", line 98, in start\n    raise err\n  File \"/Users/shaikmohamedimran/IdeaProjects/Farmstack 2.0/venv/lib/python3.10/site-packages/selenium/webdriver/common/service.py\", line 88, in start\n    self._start_process(self.path)\n  File \"/Users/shaikmohamedimran/IdeaProjects/Farmstack 2.0/venv/lib/python3.10/site-packages/selenium/webdriver/common/service.py\", line 209, in _start_process\n    raise WebDriverException(\n"}, "start": 1690363146309, "stop": 1690363147740}, {"name": "init_driver", "status": "broken", "statusDetails": {"message": "selenium.common.exceptions.WebDriverException: Message: 'chromedriver.exe' executable needs to be in PATH. Please see https://chromedriver.chromium.org/home\n\n", "trace": "  File \"/Users/shaikmohamedimran/IdeaProjects/Farmstack 2.0/venv/lib/python3.10/site-packages/pluggy/_callers.py\", line 39, in _multicall\n    res = hook_impl.function(*args)\n  File \"/Users/shaikmohamedimran/IdeaProjects/Farmstack 2.0/venv/lib/python3.10/site-packages/_pytest/fixtures.py\", line 1129, in pytest_fixture_setup\n    result = call_fixture_func(fixturefunc, request, kwargs)\n  File \"/Users/shaikmohamedimran/IdeaProjects/Farmstack 2.0/venv/lib/python3.10/site-packages/_pytest/fixtures.py\", line 901, in call_fixture_func\n    fixture_result = next(generator)\n  File \"/Users/shaikmohamedimran/IdeaProjects/Farmstack 2.0/Testcases/confitest.py\", line 18, in init_driver\n    driver = webdriver.Chrome(service=chrome_service)\n  File \"/Users/shaikmohamedimran/IdeaProjects/Farmstack 2.0/venv/lib/python3.10/site-packages/selenium/webdriver/chrome/webdriver.py\", line 80, in __init__\n    super().__init__(\n  File \"/Users/shaikmohamedimran/IdeaProjects/Farmstack 2.0/venv/lib/python3.10/site-packages/selenium/webdriver/chromium/webdriver.py\", line 101, in __init__\n    self.service.start()\n  File \"/Users/shaikmohamedimran/IdeaProjects/Farmstack 2.0/venv/lib/python3.10/site-packages/selenium/webdriver/common/service.py\", line 98, in start\n    raise err\n  File \"/Users/shaikmohamedimran/IdeaProjects/Farmstack 2.0/venv/lib/python3.10/site-packages/selenium/webdriver/common/service.py\", line 88, in start\n    self._start_process(self.path)\n  File \"/Users/shaikmohamedimran/IdeaProjects/Farmstack 2.0/venv/lib/python3.10/site-packages/selenium/webdriver/common/service.py\", line 209, in _start_process\n    raise WebDriverException(\n"}, "start": 1690363147767, "stop": 1690363148165}, {"name": "init_driver", "status": "broken", "statusDetails": {"message": "selenium.common.exceptions.WebDriverException: Message: 'chromedriver.exe' executable needs to be in PATH. Please see https://chromedriver.chromium.org/home\n\n", "trace": "  File \"/Users/shaikmohamedimran/IdeaProjects/Farmstack 2.0/venv/lib/python3.10/site-packages/pluggy/_callers.py\", line 39, in _multicall\n    res = hook_impl.function(*args)\n  File \"/Users/shaikmohamedimran/IdeaProjects/Farmstack 2.0/venv/lib/python3.10/site-packages/_pytest/fixtures.py\", line 1129, in pytest_fixture_setup\n    result = call_fixture_func(fixturefunc, request, kwargs)\n  File \"/Users/shaikmohamedimran/IdeaProjects/Farmstack 2.0/venv/lib/python3.10/site-packages/_pytest/fixtures.py\", line 901, in call_fixture_func\n    fixture_result = next(generator)\n  File \"/Users/shaikmohamedimran/IdeaProjects/Farmstack 2.0/Testcases/confitest.py\", line 18, in init_driver\n    driver = webdriver.Chrome(service=chrome_service)\n  File \"/Users/shaikmohamedimran/IdeaProjects/Farmstack 2.0/venv/lib/python3.10/site-packages/selenium/webdriver/chrome/webdriver.py\", line 80, in __init__\n    super().__init__(\n  File \"/Users/shaikmohamedimran/IdeaProjects/Farmstack 2.0/venv/lib/python3.10/site-packages/selenium/webdriver/chromium/webdriver.py\", line 101, in __init__\n    self.service.start()\n  File \"/Users/shaikmohamedimran/IdeaProjects/Farmstack 2.0/venv/lib/python3.10/site-packages/selenium/webdriver/common/service.py\", line 98, in start\n    raise err\n  File \"/Users/shaikmohamedimran/IdeaProjects/Farmstack 2.0/venv/lib/python3.10/site-packages/selenium/webdriver/common/service.py\", line 88, in start\n    self._start_process(self.path)\n  File \"/Users/shaikmohamedimran/IdeaProjects/Farmstack 2.0/venv/lib/python3.10/site-packages/selenium/webdriver/common/service.py\", line 209, in _start_process\n    raise WebDriverException(\n"}, "start": 1690363148192, "stop": 1690363148578}, {"name": "init_driver", "status": "broken", "statusDetails": {"message": "selenium.common.exceptions.WebDriverException: Message: 'chromedriver.exe' executable needs to be in PATH. Please see https://chromedriver.chromium.org/home\n\n", "trace": "  File \"/Users/shaikmohamedimran/IdeaProjects/Farmstack 2.0/venv/lib/python3.10/site-packages/pluggy/_callers.py\", line 39, in _multicall\n    res = hook_impl.function(*args)\n  File \"/Users/shaikmohamedimran/IdeaProjects/Farmstack 2.0/venv/lib/python3.10/site-packages/_pytest/fixtures.py\", line 1129, in pytest_fixture_setup\n    result = call_fixture_func(fixturefunc, request, kwargs)\n  File \"/Users/shaikmohamedimran/IdeaProjects/Farmstack 2.0/venv/lib/python3.10/site-packages/_pytest/fixtures.py\", line 901, in call_fixture_func\n    fixture_result = next(generator)\n  File \"/Users/shaikmohamedimran/IdeaProjects/Farmstack 2.0/Testcases/confitest.py\", line 18, in init_driver\n    driver = webdriver.Chrome(service=chrome_service)\n  File \"/Users/shaikmohamedimran/IdeaProjects/Farmstack 2.0/venv/lib/python3.10/site-packages/selenium/webdriver/chrome/webdriver.py\", line 80, in __init__\n    super().__init__(\n  File \"/Users/shaikmohamedimran/IdeaProjects/Farmstack 2.0/venv/lib/python3.10/site-packages/selenium/webdriver/chromium/webdriver.py\", line 101, in __init__\n    self.service.start()\n  File \"/Users/shaikmohamedimran/IdeaProjects/Farmstack 2.0/venv/lib/python3.10/site-packages/selenium/webdriver/common/service.py\", line 98, in start\n    raise err\n  File \"/Users/shaikmohamedimran/IdeaProjects/Farmstack 2.0/venv/lib/python3.10/site-packages/selenium/webdriver/common/service.py\", line 88, in start\n    self._start_process(self.path)\n  File \"/Users/shaikmohamedimran/IdeaProjects/Farmstack 2.0/venv/lib/python3.10/site-packages/selenium/webdriver/common/service.py\", line 209, in _start_process\n    raise WebDriverException(\n"}, "start": 1690363148606, "stop": 1690363148979}], "start": 1690363148606, "stop": 1690363149005}